{"name": "test_ZB_NP_21_22", "status": "broken", "statusDetails": {"message": "ValueError: {'code': -32000, 'message': 'the tx data is invalid: the func is not exist'}", "trace": "new_validator_client = <tests.lib.client.Client object at 0x00000269F6DD58D0>\n\n    def test_ZB_NP_21_22(new_validator_client):\n        new_validator_client.node.stop()\n        economic = new_validator_client.economic\n        node = economic.env.get_consensus_node_by_index(0)\n    \n        initial_validator, slashing_node_list = gen_validator_list(economic.env.consensus_node_id_list(), new_validator_client.node.node_id)\n    \n>       set_slashing(initial_validator, slashing_node_list, node, economic, \"1001\")\n\neconomic   = <tests.lib.economic.Economic object at 0x00000269F6DD54A8>\ninitial_validator = ['488fb1c783f7ac6a20d320e8442ddebe8cf983f5eda7effd00b919afdcf31dcd10e6b2bcee158245fef3a587e0248bea8cf8f6905af833623d03...b2046a77afb48a13f875c17d674421eda9c5345c32d9378490326d628e9f9b60392fcf7832ba82c9ebf5953573d6f93878c24f77e9cb53ee59fec']\nnew_validator_client = <tests.lib.client.Client object at 0x00000269F6DD58D0>\nnode       = <environment.node.Node object at 0x00000269F51BE9B0>\nslashing_node_list = ['cfdf43591661d0107b7389a0ef68a2681cdf67d93183e36201acb631920cee349d4c6d7e8557602e101df0fe6b2e6808c66e0a27a2942096348f...0a9bf5bf7c6f5fb2abbeea3546d6557cec02992f7753f99c2e39f87fdbdb6280d7fc8a243518ef27834e55eb03ad6d8ef2f627b8f0001ee185300']\n\ntests\\ppos\\test_slashing_zero.py:303: \n_ _ _ _ _ _ _ _ _ _ _ _ _ _ _ _ _ _ _ _ _ _ _ _ _ _ _ _ _ _ _ _ _ _ _ _ _ _ _ _ _ _ _ _ _ _ _ _ _ _ _ _ _ _ _ _ _ _ _ _ _ _ _ _ _ _ _ _ _ _ _ _ _ _ _ _ _ _ _ _ _ _ _ _ _ _ _ _ _ _ _ _ _ _ _ _ _ _ _ _ _ _ _ _\ntests\\ppos\\test_slashing_zero.py:58: in set_slashing\n    assert_set_validator_list(node, do[state])\ntests\\ppos\\test_slashing_zero.py:28: in assert_set_validator_list\n    result = node.debug.setValidatorList(validator_list, pri_key)\nc:\\users\\hietel\\appdata\\local\\programs\\python\\python37\\lib\\site-packages\\client_sdk_python\\debug.py:22: in setValidatorList\n    return send_obj_transaction(self, data, self.web3.stakingAddress, pri_key, transaction_cfg)\nc:\\users\\hietel\\appdata\\local\\programs\\python\\python37\\lib\\site-packages\\client_sdk_python\\utils\\transactions.py:72: in send_obj_transaction\n    tx_hash = HexBytes(obj.web3.platon.sendRawTransaction(signed_data)).hex()\nc:\\users\\hietel\\appdata\\local\\programs\\python\\python37\\lib\\site-packages\\client_sdk_python\\eth.py:300: in sendRawTransaction\n    [raw_transaction],\n_ _ _ _ _ _ _ _ _ _ _ _ _ _ _ _ _ _ _ _ _ _ _ _ _ _ _ _ _ _ _ _ _ _ _ _ _ _ _ _ _ _ _ _ _ _ _ _ _ _ _ _ _ _ _ _ _ _ _ _ _ _ _ _ _ _ _ _ _ _ _ _ _ _ _ _ _ _ _ _ _ _ _ _ _ _ _ _ _ _ _ _ _ _ _ _ _ _ _ _ _ _ _ _\n\nself = <client_sdk_python.manager.RequestManager object at 0x00000269F6FAB588>, method = 'platon_sendRawTransaction'\nparams = [HexBytes('0xf9017c028405f5e1008303345094100000000000000000000000000000000000000280b90115f901128382076cb9010bf90108b84...70ef30ce8f53a2469599c87d04b165fe10269e6dfd18c1157ca036f0c0a679be32cb58d7767c69d23d6675fa549cf59045c87d0bd4f3aa93915d')]\n\n    def request_blocking(self, method, params):\n        \"\"\"\n        Make a synchronous request using the provider\n        \"\"\"\n        response = self._make_request(method, params)\n    \n        if \"error\" in response:\n>           raise ValueError(response[\"error\"])\nE           ValueError: {'code': -32000, 'message': 'the tx data is invalid: the func is not exist'}\n\nmethod     = 'platon_sendRawTransaction'\nparams     = [HexBytes('0xf9017c028405f5e1008303345094100000000000000000000000000000000000000280b90115f901128382076cb9010bf90108b84...70ef30ce8f53a2469599c87d04b165fe10269e6dfd18c1157ca036f0c0a679be32cb58d7767c69d23d6675fa549cf59045c87d0bd4f3aa93915d')]\nresponse   = {'error': {'code': -32000, 'message': 'the tx data is invalid: the func is not exist'}, 'id': 3, 'jsonrpc': '2.0'}\nself       = <client_sdk_python.manager.RequestManager object at 0x00000269F6FAB588>\n\nc:\\users\\hietel\\appdata\\local\\programs\\python\\python37\\lib\\site-packages\\client_sdk_python\\manager.py:112: ValueError"}, "attachments": [{"name": "env log", "source": "17c48242-e7e1-4e78-a394-30f69fa56c3f-attachment.uri", "type": "text/uri-list"}, {"name": "env status", "source": "bbcd1a44-e712-4c95-a997-3b4ef82c6e71-attachment.txt", "type": "text/plain"}, {"name": "log", "source": "65864818-a328-439a-a3dc-1f019d6c5429-attachment.txt", "type": "text/plain"}], "start": 1586653355169, "stop": 1586653355464, "uuid": "694a07e7-afc2-4c24-9329-c00b1e0037e4", "historyId": "11ce6cf3ccb349a99696835ca66cbb2b", "testCaseId": "3dab14bfe663a469aa8ec9aa53d44234", "fullName": "tests.ppos.test_slashing_zero#test_ZB_NP_21_22", "labels": [{"name": "parentSuite", "value": "tests.ppos"}, {"name": "suite", "value": "test_slashing_zero"}, {"name": "host", "value": "hietel"}, {"name": "thread", "value": "25124-MainThread"}, {"name": "framework", "value": "pytest"}, {"name": "language", "value": "cpython3"}, {"name": "package", "value": "tests.ppos.test_slashing_zero"}]}